ERROR:root:'followers'
Traceback (most recent call last):
  File "c:\Users\natha\Documents\GitHub\arduino-serial-monitor\python.py", line 91, in <module>
    followers = data['followers']
                ~~~~^^^^^^^^^^^^^
KeyError: 'followers'
ERROR:root:'followers'
Traceback (most recent call last):
  File "c:\Users\natha\Documents\GitHub\arduino-serial-monitor\python.py", line 91, in <module>
    followers = data['followers']
                ~~~~^^^^^^^^^^^^^
KeyError: 'followers'
ERROR:root:'followers'
Traceback (most recent call last):
  File "c:\Users\natha\Documents\GitHub\arduino-serial-monitor\python.py", line 91, in <module>
    followers = data['followers']
                ~~~~^^^^^^^^^^^^^
KeyError: 'followers'
ERROR:root:'followers'
Traceback (most recent call last):
  File "c:\Users\natha\Documents\GitHub\arduino-serial-monitor\python.py", line 97, in <module>
    followers = data['followers']
                ~~~~^^^^^^^^^^^^^
KeyError: 'followers'
ERROR:root:'followers'
Traceback (most recent call last):
  File "c:\Users\natha\Documents\GitHub\arduino-serial-monitor\python.py", line 97, in <module>
    followers = data['followers']
                ~~~~^^^^^^^^^^^^^
KeyError: 'followers'
ERROR:root:'followers'
Traceback (most recent call last):
  File "c:\Users\natha\Documents\GitHub\arduino-serial-monitor\python.py", line 97, in <module>
    followers = data['followers']
                ~~~~^^^^^^^^^^^^^
KeyError: 'followers'
ERROR:root:'followers'
Traceback (most recent call last):
  File "c:\Users\natha\Documents\GitHub\arduino-serial-monitor\python.py", line 97, in <module>
    followers = data['followers']
                ~~~~^^^^^^^^^^^^^
KeyError: 'followers'
ERROR:root:'followers'
Traceback (most recent call last):
  File "c:\Users\natha\Documents\GitHub\arduino-serial-monitor\python.py", line 97, in <module>
    followers = data['followers']
                ~~~~^^^^^^^^^^^^^
KeyError: 'followers'
ERROR:root:'followers'
Traceback (most recent call last):
  File "c:\Users\natha\Documents\GitHub\arduino-serial-monitor\python.py", line 97, in <module>
    followers = data['followers']
                ~~~~^^^^^^^^^^^^^
KeyError: 'followers'
ERROR:root:'followers'
Traceback (most recent call last):
  File "c:\Users\natha\Documents\GitHub\arduino-serial-monitor\python.py", line 97, in <module>
    followers = data['followers']
                ~~~~^^^^^^^^^^^^^
KeyError: 'followers'
ERROR:root:'followers'
Traceback (most recent call last):
  File "c:\Users\natha\Documents\GitHub\arduino-serial-monitor\python.py", line 97, in <module>
    followers = data['followers']
                ~~~~^^^^^^^^^^^^^
KeyError: 'followers'
ERROR:root:'followers'
Traceback (most recent call last):
  File "c:\Users\natha\Documents\GitHub\arduino-serial-monitor\python.py", line 97, in <module>
    followers = data['followers']
                ~~~~^^^^^^^^^^^^^
KeyError: 'followers'
ERROR:root:'followers'
Traceback (most recent call last):
  File "c:\Users\natha\Documents\GitHub\arduino-serial-monitor\python.py", line 97, in <module>
    followers = data['followers']
                ~~~~^^^^^^^^^^^^^
KeyError: 'followers'
ERROR:root:'followers'
Traceback (most recent call last):
  File "c:\Users\natha\Documents\GitHub\arduino-serial-monitor\python.py", line 97, in <module>
    followers = data['followers']
                ~~~~^^^^^^^^^^^^^
KeyError: 'followers'
ERROR:root:'followers'
Traceback (most recent call last):
  File "c:\Users\natha\Documents\GitHub\arduino-serial-monitor\python.py", line 97, in <module>
    followers = data['followers']
                ~~~~^^^^^^^^^^^^^
KeyError: 'followers'
ERROR:root:'followers'
Traceback (most recent call last):
  File "c:\Users\natha\Documents\GitHub\arduino-serial-monitor\python.py", line 97, in <module>
    followers = data['followers']
                ~~~~^^^^^^^^^^^^^
KeyError: 'followers'
ERROR:root:'followers'
Traceback (most recent call last):
  File "c:\Users\natha\Documents\GitHub\arduino-serial-monitor\python.py", line 97, in <module>
    followers = data['followers']
                ~~~~^^^^^^^^^^^^^
KeyError: 'followers'
ERROR:root:'followers'
Traceback (most recent call last):
  File "c:\Users\natha\Documents\GitHub\arduino-serial-monitor\python.py", line 97, in <module>
    followers = data['followers']
                ~~~~^^^^^^^^^^^^^
KeyError: 'followers'
ERROR:root:'followers'
Traceback (most recent call last):
  File "c:\Users\natha\Documents\GitHub\arduino-serial-monitor\python.py", line 97, in <module>
    followers = data['followers']
                ~~~~^^^^^^^^^^^^^
KeyError: 'followers'
ERROR:root:'followers'
Traceback (most recent call last):
  File "c:\Users\natha\Documents\GitHub\arduino-serial-monitor\python.py", line 97, in <module>
    followers = data['followers']
                ~~~~^^^^^^^^^^^^^
KeyError: 'followers'
ERROR:root:'followers'
Traceback (most recent call last):
  File "c:\Users\natha\Documents\GitHub\arduino-serial-monitor\python.py", line 97, in <module>
    followers = data['followers']
                ~~~~^^^^^^^^^^^^^
KeyError: 'followers'
ERROR:root:'followers'
Traceback (most recent call last):
  File "c:\Users\natha\Documents\GitHub\arduino-serial-monitor\python.py", line 97, in <module>
    followers = data['followers']
                ~~~~^^^^^^^^^^^^^
KeyError: 'followers'
ERROR:root:'followers'
Traceback (most recent call last):
  File "c:\Users\natha\Documents\GitHub\arduino-serial-monitor\python.py", line 97, in <module>
    followers = data['followers']
                ~~~~^^^^^^^^^^^^^
KeyError: 'followers'
ERROR:root:'followers'
Traceback (most recent call last):
  File "c:\Users\natha\Documents\GitHub\arduino-serial-monitor\python.py", line 97, in <module>
    followers = data['followers']
                ~~~~^^^^^^^^^^^^^
KeyError: 'followers'
ERROR:root:'followers'
Traceback (most recent call last):
  File "c:\Users\natha\Documents\GitHub\arduino-serial-monitor\python.py", line 97, in <module>
    followers = data['followers']
                ~~~~^^^^^^^^^^^^^
KeyError: 'followers'
ERROR:root:'followers'
Traceback (most recent call last):
  File "c:\Users\natha\Documents\GitHub\arduino-serial-monitor\python.py", line 97, in <module>
    followers = data['followers']
                ~~~~^^^^^^^^^^^^^
KeyError: 'followers'
ERROR:root:'followers'
Traceback (most recent call last):
  File "c:\Users\natha\Documents\GitHub\arduino-serial-monitor\python.py", line 97, in <module>
    followers = data['followers']
                ~~~~^^^^^^^^^^^^^
KeyError: 'followers'
ERROR:root:'followers'
Traceback (most recent call last):
  File "c:\Users\natha\Documents\GitHub\arduino-serial-monitor\python.py", line 97, in <module>
    followers = data['followers']
                ~~~~^^^^^^^^^^^^^
KeyError: 'followers'
ERROR:root:'followers'
Traceback (most recent call last):
  File "c:\Users\natha\Documents\GitHub\arduino-serial-monitor\python.py", line 97, in <module>
    followers = data['followers']
                ~~~~^^^^^^^^^^^^^
KeyError: 'followers'
ERROR:root:'followers'
Traceback (most recent call last):
  File "c:\Users\natha\Documents\GitHub\arduino-serial-monitor\python.py", line 97, in <module>
    followers = data['followers']
                ~~~~^^^^^^^^^^^^^
KeyError: 'followers'
ERROR:root:'followers'
Traceback (most recent call last):
  File "c:\Users\natha\Documents\GitHub\arduino-serial-monitor\python.py", line 97, in <module>
    followers = data['followers']
                ~~~~^^^^^^^^^^^^^
KeyError: 'followers'
ERROR:root:'followers'
Traceback (most recent call last):
  File "c:\Users\natha\Documents\GitHub\arduino-serial-monitor\python.py", line 97, in <module>
    followers = data['followers']
                ~~~~^^^^^^^^^^^^^
KeyError: 'followers'
ERROR:root:'followers'
Traceback (most recent call last):
  File "c:\Users\natha\Documents\GitHub\arduino-serial-monitor\python.py", line 97, in <module>
    followers = data['followers']
                ~~~~^^^^^^^^^^^^^
KeyError: 'followers'
ERROR:root:'followers'
Traceback (most recent call last):
  File "c:\Users\natha\Documents\GitHub\arduino-serial-monitor\python.py", line 97, in <module>
    followers = data['followers']
                ~~~~^^^^^^^^^^^^^
KeyError: 'followers'
ERROR:root:'followers'
Traceback (most recent call last):
  File "c:\Users\natha\Documents\GitHub\arduino-serial-monitor\python.py", line 97, in <module>
    followers = data['followers']
                ~~~~^^^^^^^^^^^^^
KeyError: 'followers'
ERROR:root:'followers'
Traceback (most recent call last):
  File "c:\Users\natha\Documents\GitHub\arduino-serial-monitor\python.py", line 97, in <module>
    followers = data['followers']
                ~~~~^^^^^^^^^^^^^
KeyError: 'followers'
ERROR:root:'followers'
Traceback (most recent call last):
  File "c:\Users\natha\Documents\GitHub\arduino-serial-monitor\python.py", line 97, in <module>
    followers = data['followers']
                ~~~~^^^^^^^^^^^^^
KeyError: 'followers'
ERROR:root:'followers'
Traceback (most recent call last):
  File "c:\Users\natha\Documents\GitHub\arduino-serial-monitor\python.py", line 97, in <module>
    followers = data['followers']
                ~~~~^^^^^^^^^^^^^
KeyError: 'followers'
ERROR:root:'followers'
Traceback (most recent call last):
  File "c:\Users\natha\Documents\GitHub\arduino-serial-monitor\python.py", line 97, in <module>
    followers = data['followers']
                ~~~~^^^^^^^^^^^^^
KeyError: 'followers'
ERROR:root:'followers'
Traceback (most recent call last):
  File "c:\Users\natha\Documents\GitHub\arduino-serial-monitor\python.py", line 97, in <module>
    followers = data['followers']
                ~~~~^^^^^^^^^^^^^
KeyError: 'followers'
ERROR:root:'followers'
Traceback (most recent call last):
  File "c:\Users\natha\Documents\GitHub\arduino-serial-monitor\python.py", line 97, in <module>
    followers = data['followers']
                ~~~~^^^^^^^^^^^^^
KeyError: 'followers'
ERROR:root:'followers'
Traceback (most recent call last):
  File "c:\Users\natha\Documents\GitHub\arduino-serial-monitor\python.py", line 97, in <module>
    followers = data['followers']
                ~~~~^^^^^^^^^^^^^
KeyError: 'followers'
ERROR:root:'followers'
Traceback (most recent call last):
  File "c:\Users\natha\Documents\GitHub\arduino-serial-monitor\python.py", line 97, in <module>
    followers = data['followers']
                ~~~~^^^^^^^^^^^^^
KeyError: 'followers'
ERROR:root:'followers'
Traceback (most recent call last):
  File "c:\Users\natha\Documents\GitHub\arduino-serial-monitor\python.py", line 97, in <module>
    followers = data['followers']
                ~~~~^^^^^^^^^^^^^
KeyError: 'followers'
ERROR:root:'followers'
Traceback (most recent call last):
  File "c:\Users\natha\Documents\GitHub\arduino-serial-monitor\python.py", line 97, in <module>
    followers = data['followers']
                ~~~~^^^^^^^^^^^^^
KeyError: 'followers'
ERROR:root:'followers'
Traceback (most recent call last):
  File "c:\Users\natha\Documents\GitHub\arduino-serial-monitor\python.py", line 97, in <module>
    followers = data['followers']
                ~~~~^^^^^^^^^^^^^
KeyError: 'followers'
ERROR:root:'followers'
Traceback (most recent call last):
  File "c:\Users\natha\Documents\GitHub\arduino-serial-monitor\python.py", line 97, in <module>
    followers = data['followers']
                ~~~~^^^^^^^^^^^^^
KeyError: 'followers'
ERROR:root:'followers'
Traceback (most recent call last):
  File "c:\Users\natha\Documents\GitHub\arduino-serial-monitor\python.py", line 97, in <module>
    followers = data['followers']
                ~~~~^^^^^^^^^^^^^
KeyError: 'followers'
ERROR:root:'followers'
Traceback (most recent call last):
  File "c:\Users\natha\Documents\GitHub\arduino-serial-monitor\python.py", line 97, in <module>
    followers = data['followers']
                ~~~~^^^^^^^^^^^^^
KeyError: 'followers'
ERROR:pystray._base:An error occurred when calling message handler
Traceback (most recent call last):
  File "C:\Users\natha\AppData\Local\Programs\Python\Python312\Lib\site-packages\pystray\_win32.py", line 412, in _dispatcher
    return int(icon._message_handlers.get(
               ^^^^^^^^^^^^^^^^^^^^^^^^^^^
  File "C:\Users\natha\AppData\Local\Programs\Python\Python312\Lib\site-packages\pystray\_win32.py", line 224, in _on_notify
    descriptors[index - 1](self)
  File "C:\Users\natha\AppData\Local\Programs\Python\Python312\Lib\site-packages\pystray\_base.py", line 328, in inner
    callback(self)
  File "C:\Users\natha\AppData\Local\Programs\Python\Python312\Lib\site-packages\pystray\_base.py", line 453, in __call__
    return self._action(icon, self)
           ^^^^^^^^^^^^^^^^^^^^^^^^
  File "c:\Users\natha\Documents\GitHub\arduino-serial-monitor\python.py", line 45, in on_quit_callback
    response = ser.readline().decode().strip()
               ^^^^^^^^^^^^^^^^^^^^^^^
UnicodeDecodeError: 'utf-8' codec can't decode byte 0xa1 in position 0: invalid start byte
ERROR:root:'followers'
Traceback (most recent call last):
  File "c:\Users\natha\Documents\GitHub\arduino-serial-monitor\python.py", line 97, in <module>
    followers = data['followers']
                ~~~~^^^^^^^^^^^^^
KeyError: 'followers'
ERROR:root:'followers'
Traceback (most recent call last):
  File "c:\Users\natha\Documents\GitHub\arduino-serial-monitor\python.py", line 97, in <module>
    followers = data['followers']
                ~~~~^^^^^^^^^^^^^
KeyError: 'followers'
ERROR:root:'followers'
Traceback (most recent call last):
  File "c:\Users\natha\Documents\GitHub\arduino-serial-monitor\python.py", line 97, in <module>
    followers = data['followers']
                ~~~~^^^^^^^^^^^^^
KeyError: 'followers'
ERROR:root:'followers'
Traceback (most recent call last):
  File "c:\Users\natha\Documents\GitHub\arduino-serial-monitor\python.py", line 97, in <module>
    followers = data['followers']
                ~~~~^^^^^^^^^^^^^
KeyError: 'followers'
ERROR:root:'followers'
Traceback (most recent call last):
  File "c:\Users\natha\Documents\GitHub\arduino-serial-monitor\python.py", line 97, in <module>
    followers = data['followers']
                ~~~~^^^^^^^^^^^^^
KeyError: 'followers'
ERROR:root:'followers'
Traceback (most recent call last):
  File "c:\Users\natha\Documents\GitHub\arduino-serial-monitor\python.py", line 97, in <module>
    followers = data['followers']
                ~~~~^^^^^^^^^^^^^
KeyError: 'followers'
ERROR:root:'followers'
Traceback (most recent call last):
  File "c:\Users\natha\Documents\GitHub\arduino-serial-monitor\python.py", line 97, in <module>
    followers = data['followers']
                ~~~~^^^^^^^^^^^^^
KeyError: 'followers'
ERROR:root:'followers'
Traceback (most recent call last):
  File "c:\Users\natha\Documents\GitHub\arduino-serial-monitor\python.py", line 97, in <module>
    followers = data['followers']
                ~~~~^^^^^^^^^^^^^
KeyError: 'followers'
ERROR:root:'followers'
Traceback (most recent call last):
  File "c:\Users\natha\Documents\GitHub\arduino-serial-monitor\python.py", line 97, in <module>
    followers = data['followers']
                ~~~~^^^^^^^^^^^^^
KeyError: 'followers'
ERROR:root:'followers'
Traceback (most recent call last):
  File "c:\Users\natha\Documents\GitHub\arduino-serial-monitor\python.py", line 97, in <module>
    followers = data['followers']
                ~~~~^^^^^^^^^^^^^
KeyError: 'followers'
ERROR:root:'followers'
Traceback (most recent call last):
  File "c:\Users\natha\Documents\GitHub\arduino-serial-monitor\python.py", line 97, in <module>
    followers = data['followers']
                ~~~~^^^^^^^^^^^^^
KeyError: 'followers'
ERROR:root:'followers'
Traceback (most recent call last):
  File "c:\Users\natha\Documents\GitHub\arduino-serial-monitor\python.py", line 97, in <module>
    followers = data['followers']
                ~~~~^^^^^^^^^^^^^
KeyError: 'followers'
ERROR:root:'followers'
Traceback (most recent call last):
  File "c:\Users\natha\Documents\GitHub\arduino-serial-monitor\python.py", line 97, in <module>
    followers = data['followers']
                ~~~~^^^^^^^^^^^^^
KeyError: 'followers'
ERROR:root:'followers'
Traceback (most recent call last):
  File "c:\Users\natha\Documents\GitHub\arduino-serial-monitor\python.py", line 97, in <module>
    followers = data['followers']
                ~~~~^^^^^^^^^^^^^
KeyError: 'followers'
ERROR:root:'followers'
Traceback (most recent call last):
  File "c:\Users\natha\Documents\GitHub\arduino-serial-monitor\python.py", line 97, in <module>
    followers = data['followers']
                ~~~~^^^^^^^^^^^^^
KeyError: 'followers'
ERROR:root:'followers'
Traceback (most recent call last):
  File "c:\Users\natha\Documents\GitHub\arduino-serial-monitor\python.py", line 97, in <module>
    followers = data['followers']
                ~~~~^^^^^^^^^^^^^
KeyError: 'followers'
ERROR:root:'followers'
Traceback (most recent call last):
  File "c:\Users\natha\Documents\GitHub\arduino-serial-monitor\python.py", line 97, in <module>
    followers = data['followers']
                ~~~~^^^^^^^^^^^^^
KeyError: 'followers'
ERROR:root:Attempting to use a port that is not open
Traceback (most recent call last):
  File "c:\Users\natha\Documents\GitHub\arduino-serial-monitor\python.py", line 92, in <module>
    ser.write(f'INFO:CPU:{cpu_usage},MEM_RAW:{memory_usage_raw},MEM_TOTAL:{memory_total},GPU:{gpu_usage},TEMP:{gpu_temp},TIME:{timePrint},VOL:{volumePercent}\n'.encode())
  File "C:\Users\natha\AppData\Local\Programs\Python\Python312\Lib\site-packages\serial\serialwin32.py", line 306, in write
    raise PortNotOpenError()
serial.serialutil.PortNotOpenError: Attempting to use a port that is not open
